2022-11-18 21:55:21,380 [MainThread] INFO: setting language to: en_US.UTF-8
2022-11-18 21:55:21,468 [MainThread] INFO: 38 custom mappings(s)
2022-11-18 21:55:21,522 [Dummy-1] INFO: set_stroke_filename(/home/johannes/.local/share/plover/strokes.log)
2022-11-18 21:55:21,522 [Dummy-1] INFO: loading system: English Stenotype
2022-11-18 21:55:21,522 [Dummy-1] ERROR: engine start failed
Traceback (most recent call last):
  File "/usr/lib/python3/dist-packages/plover/engine.py", line 136, in run
    if func(*args, **kwargs):
  File "/usr/lib/python3/dist-packages/plover/engine.py", line 149, in _start
    self._update(full=True)
  File "/usr/lib/python3/dist-packages/plover/engine.py", line 196, in _update
    system.setup(system_name)
  File "/usr/lib/python3/dist-packages/plover/system/__init__.py", line 62, in setup
    system_symbols[symbol] = init(mod)
  File "/usr/lib/python3/dist-packages/plover/system/__init__.py", line 44, in <lambda>
    'SUFFIX_KEYS'              : lambda mod: _suffix_keys(mod.SUFFIX_KEYS),
  File "/usr/lib/python3/dist-packages/plover/system/__init__.py", line 36, in _suffix_keys
    assert isinstance(keys, collections.Sequence)
AttributeError: module 'collections' has no attribute 'Sequence'
2022-11-18 21:55:54,739 [Dummy-1] INFO: loading system: English Stenotype
2022-11-18 21:55:54,739 [Dummy-1] ERROR: engine update failed
Traceback (most recent call last):
  File "/usr/lib/python3/dist-packages/plover/engine.py", line 136, in run
    if func(*args, **kwargs):
  File "/usr/lib/python3/dist-packages/plover/engine.py", line 196, in _update
    system.setup(system_name)
  File "/usr/lib/python3/dist-packages/plover/system/__init__.py", line 62, in setup
    system_symbols[symbol] = init(mod)
  File "/usr/lib/python3/dist-packages/plover/system/__init__.py", line 44, in <lambda>
    'SUFFIX_KEYS'              : lambda mod: _suffix_keys(mod.SUFFIX_KEYS),
  File "/usr/lib/python3/dist-packages/plover/system/__init__.py", line 36, in _suffix_keys
    assert isinstance(keys, collections.Sequence)
AttributeError: module 'collections' has no attribute 'Sequence'
2022-11-18 21:55:59,627 [Dummy-1] INFO: loading system: English Stenotype
2022-11-18 21:55:59,627 [Dummy-1] ERROR: engine update failed
Traceback (most recent call last):
  File "/usr/lib/python3/dist-packages/plover/engine.py", line 136, in run
    if func(*args, **kwargs):
  File "/usr/lib/python3/dist-packages/plover/engine.py", line 196, in _update
    system.setup(system_name)
  File "/usr/lib/python3/dist-packages/plover/system/__init__.py", line 62, in setup
    system_symbols[symbol] = init(mod)
  File "/usr/lib/python3/dist-packages/plover/system/__init__.py", line 44, in <lambda>
    'SUFFIX_KEYS'              : lambda mod: _suffix_keys(mod.SUFFIX_KEYS),
  File "/usr/lib/python3/dist-packages/plover/system/__init__.py", line 36, in _suffix_keys
    assert isinstance(keys, collections.Sequence)
AttributeError: module 'collections' has no attribute 'Sequence'
2022-11-18 22:04:48,451 [MainThread] INFO: setting language to: en_US.UTF-8
2022-11-18 22:04:48,535 [MainThread] INFO: 38 custom mappings(s)
2022-11-18 22:04:48,591 [Dummy-1] INFO: set_stroke_filename(/home/johannes/.local/share/plover/strokes.log)
2022-11-18 22:04:48,591 [Dummy-1] INFO: loading system: English Stenotype
2022-11-18 22:04:48,591 [Dummy-1] ERROR: engine start failed
Traceback (most recent call last):
  File "/usr/lib/python3/dist-packages/plover/engine.py", line 136, in run
    if func(*args, **kwargs):
  File "/usr/lib/python3/dist-packages/plover/engine.py", line 149, in _start
    self._update(full=True)
  File "/usr/lib/python3/dist-packages/plover/engine.py", line 196, in _update
    system.setup(system_name)
  File "/usr/lib/python3/dist-packages/plover/system/__init__.py", line 62, in setup
    system_symbols[symbol] = init(mod)
  File "/usr/lib/python3/dist-packages/plover/system/__init__.py", line 44, in <lambda>
    'SUFFIX_KEYS'              : lambda mod: _suffix_keys(mod.SUFFIX_KEYS),
  File "/usr/lib/python3/dist-packages/plover/system/__init__.py", line 36, in _suffix_keys
    assert isinstance(keys, collections.Sequence)
AttributeError: module 'collections' has no attribute 'Sequence'
2022-11-18 22:06:22,126 [Dummy-1] INFO: loading system: English Stenotype
2022-11-18 22:06:22,126 [Dummy-1] ERROR: engine update failed
Traceback (most recent call last):
  File "/usr/lib/python3/dist-packages/plover/engine.py", line 136, in run
    if func(*args, **kwargs):
  File "/usr/lib/python3/dist-packages/plover/engine.py", line 196, in _update
    system.setup(system_name)
  File "/usr/lib/python3/dist-packages/plover/system/__init__.py", line 62, in setup
    system_symbols[symbol] = init(mod)
  File "/usr/lib/python3/dist-packages/plover/system/__init__.py", line 44, in <lambda>
    'SUFFIX_KEYS'              : lambda mod: _suffix_keys(mod.SUFFIX_KEYS),
  File "/usr/lib/python3/dist-packages/plover/system/__init__.py", line 36, in _suffix_keys
    assert isinstance(keys, collections.Sequence)
AttributeError: module 'collections' has no attribute 'Sequence'
2022-11-18 22:06:43,420 [Dummy-1] INFO: loading system: English Stenotype
2022-11-18 22:06:43,420 [Dummy-1] ERROR: engine update failed
Traceback (most recent call last):
  File "/usr/lib/python3/dist-packages/plover/engine.py", line 136, in run
    if func(*args, **kwargs):
  File "/usr/lib/python3/dist-packages/plover/engine.py", line 196, in _update
    system.setup(system_name)
  File "/usr/lib/python3/dist-packages/plover/system/__init__.py", line 62, in setup
    system_symbols[symbol] = init(mod)
  File "/usr/lib/python3/dist-packages/plover/system/__init__.py", line 44, in <lambda>
    'SUFFIX_KEYS'              : lambda mod: _suffix_keys(mod.SUFFIX_KEYS),
  File "/usr/lib/python3/dist-packages/plover/system/__init__.py", line 36, in _suffix_keys
    assert isinstance(keys, collections.Sequence)
AttributeError: module 'collections' has no attribute 'Sequence'
2022-11-18 22:07:00,848 [Dummy-1] INFO: loading system: English Stenotype
2022-11-18 22:07:00,848 [Dummy-1] ERROR: engine update failed
Traceback (most recent call last):
  File "/usr/lib/python3/dist-packages/plover/engine.py", line 136, in run
    if func(*args, **kwargs):
  File "/usr/lib/python3/dist-packages/plover/engine.py", line 196, in _update
    system.setup(system_name)
  File "/usr/lib/python3/dist-packages/plover/system/__init__.py", line 62, in setup
    system_symbols[symbol] = init(mod)
  File "/usr/lib/python3/dist-packages/plover/system/__init__.py", line 44, in <lambda>
    'SUFFIX_KEYS'              : lambda mod: _suffix_keys(mod.SUFFIX_KEYS),
  File "/usr/lib/python3/dist-packages/plover/system/__init__.py", line 36, in _suffix_keys
    assert isinstance(keys, collections.Sequence)
AttributeError: module 'collections' has no attribute 'Sequence'
2022-11-18 22:07:02,052 [Dummy-1] INFO: loading system: English Stenotype
2022-11-18 22:07:02,052 [Dummy-1] ERROR: engine update failed
Traceback (most recent call last):
  File "/usr/lib/python3/dist-packages/plover/engine.py", line 136, in run
    if func(*args, **kwargs):
  File "/usr/lib/python3/dist-packages/plover/engine.py", line 196, in _update
    system.setup(system_name)
  File "/usr/lib/python3/dist-packages/plover/system/__init__.py", line 62, in setup
    system_symbols[symbol] = init(mod)
  File "/usr/lib/python3/dist-packages/plover/system/__init__.py", line 44, in <lambda>
    'SUFFIX_KEYS'              : lambda mod: _suffix_keys(mod.SUFFIX_KEYS),
  File "/usr/lib/python3/dist-packages/plover/system/__init__.py", line 36, in _suffix_keys
    assert isinstance(keys, collections.Sequence)
AttributeError: module 'collections' has no attribute 'Sequence'
2022-11-18 22:07:12,006 [Dummy-1] INFO: loading system: English Stenotype
2022-11-18 22:07:12,007 [Dummy-1] ERROR: engine update failed
Traceback (most recent call last):
  File "/usr/lib/python3/dist-packages/plover/engine.py", line 136, in run
    if func(*args, **kwargs):
  File "/usr/lib/python3/dist-packages/plover/engine.py", line 196, in _update
    system.setup(system_name)
  File "/usr/lib/python3/dist-packages/plover/system/__init__.py", line 62, in setup
    system_symbols[symbol] = init(mod)
  File "/usr/lib/python3/dist-packages/plover/system/__init__.py", line 44, in <lambda>
    'SUFFIX_KEYS'              : lambda mod: _suffix_keys(mod.SUFFIX_KEYS),
  File "/usr/lib/python3/dist-packages/plover/system/__init__.py", line 36, in _suffix_keys
    assert isinstance(keys, collections.Sequence)
AttributeError: module 'collections' has no attribute 'Sequence'
2022-11-18 22:12:23,534 [MainThread] INFO: setting language to: en_US.UTF-8
2022-11-18 22:12:23,541 [MainThread] INFO: 38 custom mappings(s)
2022-11-18 22:12:23,653 [Dummy-1] INFO: set_stroke_filename(/home/johannes/.local/share/plover/strokes.log)
2022-11-18 22:12:23,653 [Dummy-1] INFO: loading system: English Stenotype
2022-11-18 22:12:23,765 [Dummy-1] INFO: setting machine: Gemini PR
2022-11-18 22:12:23,765 [Dummy-1] WARNING: Can't open serial port
Traceback (most recent call last):
  File "/home/runner/work/plover/plover/build/appimage/plover.AppDir/usr/lib/python3.9/site-packages/serial/serialposix.py", line 322, in open
FileNotFoundError: [Errno 2] No such file or directory: '/dev/ttyACM0'

During handling of the above exception, another exception occurred:

Traceback (most recent call last):
  File "/home/runner/work/plover/plover/build/appimage/plover.AppDir/usr/lib/python3.9/site-packages/plover/machine/base.py", line 215, in start_capture
  File "/home/runner/work/plover/plover/build/appimage/plover.AppDir/usr/lib/python3.9/site-packages/serial/serialutil.py", line 244, in __init__
  File "/home/runner/work/plover/plover/build/appimage/plover.AppDir/usr/lib/python3.9/site-packages/serial/serialposix.py", line 325, in open
serial.serialutil.SerialException: [Errno 2] could not open port /dev/ttyACM0: [Errno 2] No such file or directory: '/dev/ttyACM0'
2022-11-18 22:12:23,765 [Dummy-1] INFO: recreating /home/johannes/.local/share/plover/user.json from asset:plover:assets/user.json
2022-11-18 22:12:23,766 [Dummy-1] INFO: recreating /home/johannes/.local/share/plover/commands.json from asset:plover:assets/commands.json
2022-11-18 22:12:23,768 [Dummy-1] INFO: recreating /home/johannes/.local/share/plover/main.json from asset:plover:assets/main.json
2022-11-18 22:12:23,782 [Dummy-1] INFO: loading dictionary: /home/johannes/.local/share/plover/user.json
2022-11-18 22:12:23,782 [Dummy-1] INFO: loading dictionary: /home/johannes/.local/share/plover/commands.json
2022-11-18 22:12:23,782 [Dummy-1] INFO: loading dictionary: /home/johannes/.local/share/plover/main.json
2022-11-18 22:12:24,084 [Dummy-1] INFO: loaded 3 dictionaries in 0.303s
2022-11-18 22:12:38,141 [Dummy-1] INFO: loaded 3 dictionaries in 0.000s
2022-12-07 22:55:44,759 [MainThread] INFO: setting language to: en_US.UTF-8
2022-12-07 22:55:44,786 [MainThread] INFO: 38 custom mappings(s)
2022-12-07 22:55:45,172 [Dummy-1] INFO: set_stroke_filename(/home/johannes/.local/share/plover/strokes.log)
2022-12-07 22:55:45,173 [Dummy-1] INFO: loading system: English Stenotype
2022-12-07 22:55:45,488 [Dummy-1] INFO: setting machine: Gemini PR
2022-12-07 22:55:45,491 [Dummy-1] INFO: loading dictionary: /home/johannes/.local/share/plover/user.json
2022-12-07 22:55:45,491 [Dummy-1] INFO: loading dictionary: /home/johannes/.local/share/plover/commands.json
2022-12-07 22:55:45,492 [Dummy-1] INFO: loading dictionary: /home/johannes/.local/share/plover/main.json
2022-12-07 22:55:46,207 [Dummy-1] INFO: loaded 3 dictionaries in 0.716s
2022-12-07 22:56:00,179 [Dummy-1] INFO: setting machine: Gemini PR
2022-12-07 22:56:00,181 [Dummy-1] INFO: loaded 3 dictionaries in 0.000s
2022-12-17 04:16:50,974 [MainThread] INFO: setting language to: en_US.UTF-8
2022-12-17 04:16:50,996 [MainThread] INFO: 38 custom mappings(s)
2022-12-17 04:16:51,409 [Dummy-1] INFO: set_stroke_filename(/home/johannes/.local/share/plover/strokes.log)
2022-12-17 04:16:51,409 [Dummy-1] INFO: loading system: English Stenotype
2022-12-17 04:16:51,701 [Dummy-1] INFO: setting machine: Gemini PR
2022-12-17 04:16:51,701 [Dummy-1] WARNING: Can't open serial port
Traceback (most recent call last):
  File "/home/runner/work/plover/plover/build/appimage/plover.AppDir/usr/lib/python3.9/site-packages/serial/serialposix.py", line 322, in open
FileNotFoundError: [Errno 2] No such file or directory: '/dev/ttyACM0'

During handling of the above exception, another exception occurred:

Traceback (most recent call last):
  File "/home/runner/work/plover/plover/build/appimage/plover.AppDir/usr/lib/python3.9/site-packages/plover/machine/base.py", line 215, in start_capture
  File "/home/runner/work/plover/plover/build/appimage/plover.AppDir/usr/lib/python3.9/site-packages/serial/serialutil.py", line 244, in __init__
  File "/home/runner/work/plover/plover/build/appimage/plover.AppDir/usr/lib/python3.9/site-packages/serial/serialposix.py", line 325, in open
serial.serialutil.SerialException: [Errno 2] could not open port /dev/ttyACM0: [Errno 2] No such file or directory: '/dev/ttyACM0'
2022-12-17 04:16:51,703 [Dummy-1] INFO: loading dictionary: /home/johannes/.local/share/plover/user.json
2022-12-17 04:16:51,704 [Dummy-1] INFO: loading dictionary: /home/johannes/.local/share/plover/commands.json
2022-12-17 04:16:51,704 [Dummy-1] INFO: loading dictionary: /home/johannes/.local/share/plover/main.json
2022-12-17 04:16:52,377 [Dummy-1] INFO: loaded 3 dictionaries in 0.674s
2022-12-17 07:16:45,633 [Dummy-1] INFO: setting machine: Gemini PR
2022-12-17 07:16:45,636 [Dummy-1] INFO: loading dictionary: /home/johannes/.local/share/plover/main.json
2022-12-17 07:16:46,040 [Dummy-1] INFO: loaded 3 dictionaries in 0.404s
2022-12-17 19:30:59,038 [Dummy-1] INFO: setting machine: Gemini PR
2022-12-17 19:30:59,039 [Dummy-1] WARNING: Can't open serial port
Traceback (most recent call last):
  File "/home/runner/work/plover/plover/build/appimage/plover.AppDir/usr/lib/python3.9/site-packages/serial/serialposix.py", line 322, in open
FileNotFoundError: [Errno 2] No such file or directory: '/dev/ttyACM0'

During handling of the above exception, another exception occurred:

Traceback (most recent call last):
  File "/home/runner/work/plover/plover/build/appimage/plover.AppDir/usr/lib/python3.9/site-packages/plover/machine/base.py", line 215, in start_capture
  File "/home/runner/work/plover/plover/build/appimage/plover.AppDir/usr/lib/python3.9/site-packages/serial/serialutil.py", line 244, in __init__
  File "/home/runner/work/plover/plover/build/appimage/plover.AppDir/usr/lib/python3.9/site-packages/serial/serialposix.py", line 325, in open
serial.serialutil.SerialException: [Errno 2] could not open port /dev/ttyACM0: [Errno 2] No such file or directory: '/dev/ttyACM0'
2022-12-17 19:30:59,040 [Dummy-1] INFO: loaded 3 dictionaries in 0.000s
2022-12-20 22:33:15,733 [Dummy-1] INFO: setting machine: Gemini PR
2022-12-20 22:33:15,735 [Dummy-1] INFO: loaded 3 dictionaries in 0.000s
2022-12-21 21:48:18,044 [Dummy-1] INFO: setting machine: Gemini PR
2022-12-21 21:48:18,045 [Dummy-1] WARNING: Can't open serial port
Traceback (most recent call last):
  File "/home/runner/work/plover/plover/build/appimage/plover.AppDir/usr/lib/python3.9/site-packages/serial/serialposix.py", line 322, in open
FileNotFoundError: [Errno 2] No such file or directory: '/dev/ttyACM0'

During handling of the above exception, another exception occurred:

Traceback (most recent call last):
  File "/home/runner/work/plover/plover/build/appimage/plover.AppDir/usr/lib/python3.9/site-packages/plover/machine/base.py", line 215, in start_capture
  File "/home/runner/work/plover/plover/build/appimage/plover.AppDir/usr/lib/python3.9/site-packages/serial/serialutil.py", line 244, in __init__
  File "/home/runner/work/plover/plover/build/appimage/plover.AppDir/usr/lib/python3.9/site-packages/serial/serialposix.py", line 325, in open
serial.serialutil.SerialException: [Errno 2] could not open port /dev/ttyACM0: [Errno 2] No such file or directory: '/dev/ttyACM0'
2022-12-21 21:48:18,047 [Dummy-1] INFO: loaded 3 dictionaries in 0.000s
2022-12-21 21:48:45,037 [Dummy-1] INFO: setting machine: Gemini PR
2022-12-21 21:48:45,038 [Dummy-1] INFO: loaded 3 dictionaries in 0.000s
2022-12-21 21:48:45,082 [Dummy-1] INFO: loaded 3 dictionaries in 0.000s
2022-12-21 21:48:46,400 [Dummy-1] INFO: loaded 3 dictionaries in 0.000s
2022-12-23 04:01:01,993 [MainThread] INFO: setting language to: en_US.UTF-8
2022-12-23 04:01:02,001 [MainThread] INFO: 38 custom mappings(s)
2022-12-23 04:01:02,134 [Dummy-1] INFO: set_stroke_filename(/home/johannes/.local/share/plover/strokes.log)
2022-12-23 04:01:02,135 [Dummy-1] INFO: loading system: English Stenotype
2022-12-23 04:01:02,248 [Dummy-1] INFO: setting machine: Gemini PR
2022-12-23 04:01:02,250 [Dummy-1] INFO: loading dictionary: /home/johannes/.local/share/plover/user.json
2022-12-23 04:01:02,250 [Dummy-1] INFO: loading dictionary: /home/johannes/.local/share/plover/commands.json
2022-12-23 04:01:02,251 [Dummy-1] INFO: loading dictionary: /home/johannes/.local/share/plover/main.json
2022-12-23 04:01:02,550 [Dummy-1] INFO: loaded 3 dictionaries in 0.300s
2022-12-23 04:01:12,973 [Dummy-1] INFO: setting machine: Gemini PR
2022-12-23 04:01:12,974 [Dummy-1] INFO: loaded 3 dictionaries in 0.000s
2022-12-23 21:38:12,440 [Dummy-1] INFO: setting machine: Gemini PR
2022-12-23 21:38:12,442 [Dummy-1] INFO: loaded 3 dictionaries in 0.000s
2022-12-24 21:07:02,079 [MainThread] INFO: setting language to: en_US.UTF-8
2022-12-24 21:07:02,100 [MainThread] INFO: 38 custom mappings(s)
2022-12-24 21:07:02,436 [Dummy-1] INFO: set_stroke_filename(/home/johannes/.local/share/plover/strokes.log)
2022-12-24 21:07:02,436 [Dummy-1] INFO: loading system: English Stenotype
2022-12-24 21:07:02,767 [Dummy-1] INFO: setting machine: Gemini PR
2022-12-24 21:07:02,769 [Dummy-1] INFO: loading dictionary: /home/johannes/.local/share/plover/user.json
2022-12-24 21:07:02,770 [Dummy-1] INFO: loading dictionary: /home/johannes/.local/share/plover/commands.json
2022-12-24 21:07:02,771 [Dummy-1] INFO: loading dictionary: /home/johannes/.local/share/plover/main.json
2022-12-24 21:07:03,466 [Dummy-1] INFO: loaded 3 dictionaries in 0.697s
2022-12-24 21:07:08,468 [Dummy-1] INFO: setting machine: Gemini PR
2022-12-24 21:07:08,470 [Dummy-1] INFO: loaded 3 dictionaries in 0.000s
2022-12-24 21:23:27,900 [Dummy-1] INFO: loaded 3 dictionaries in 0.000s
2022-12-24 21:23:29,132 [Dummy-1] INFO: loaded 3 dictionaries in 0.000s
2022-12-24 21:23:30,183 [Dummy-1] INFO: loaded 3 dictionaries in 0.000s
2022-12-25 23:23:13,173 [MainThread] INFO: setting language to: en_US.UTF-8
2022-12-25 23:23:13,182 [MainThread] INFO: 38 custom mappings(s)
2022-12-25 23:23:13,312 [Dummy-1] INFO: set_stroke_filename(/home/johannes/.local/share/plover/strokes.log)
2022-12-25 23:23:13,312 [Dummy-1] INFO: loading system: English Stenotype
2022-12-25 23:23:13,430 [Dummy-1] INFO: setting machine: Gemini PR
2022-12-25 23:23:13,432 [Dummy-1] INFO: loading dictionary: /home/johannes/.local/share/plover/user.json
2022-12-25 23:23:13,432 [Dummy-1] INFO: loading dictionary: /home/johannes/.local/share/plover/commands.json
2022-12-25 23:23:13,432 [Dummy-1] INFO: loading dictionary: /home/johannes/.local/share/plover/main.json
2022-12-25 23:23:13,740 [Dummy-1] INFO: loaded 3 dictionaries in 0.308s
2022-12-25 23:23:18,786 [Dummy-1] INFO: setting machine: Gemini PR
2022-12-25 23:23:18,787 [Dummy-1] INFO: loaded 3 dictionaries in 0.000s
2022-12-25 23:23:43,464 [Dummy-1] INFO: loaded 3 dictionaries in 0.000s
2022-12-25 23:23:44,274 [Dummy-1] INFO: loaded 3 dictionaries in 0.000s
2022-12-25 23:23:45,683 [Dummy-1] INFO: loaded 3 dictionaries in 0.000s
2022-12-26 22:54:32,247 [Dummy-1] INFO: setting machine: Gemini PR
2022-12-26 22:54:32,248 [Dummy-1] INFO: loaded 3 dictionaries in 0.000s
2022-12-26 23:42:51,357 [MainThread] INFO: setting language to: en_US.UTF-8
2022-12-26 23:42:51,362 [MainThread] INFO: 38 custom mappings(s)
2022-12-26 23:42:51,429 [Dummy-1] INFO: set_stroke_filename(/home/johannes/.local/share/plover/strokes.log)
2022-12-26 23:42:51,429 [Dummy-1] INFO: loading system: English Stenotype
2022-12-26 23:42:51,542 [Dummy-1] INFO: setting machine: Gemini PR
2022-12-26 23:42:51,543 [Dummy-1] INFO: loading dictionary: /home/johannes/.local/share/plover/user.json
2022-12-26 23:42:51,543 [Dummy-1] INFO: loading dictionary: /home/johannes/.local/share/plover/commands.json
2022-12-26 23:42:51,544 [Dummy-1] INFO: loading dictionary: /home/johannes/.local/share/plover/main.json
2022-12-26 23:42:51,851 [Dummy-1] INFO: loaded 3 dictionaries in 0.309s
2022-12-28 21:49:29,717 [Dummy-1] INFO: setting machine: Gemini PR
2022-12-28 21:49:29,719 [Dummy-1] INFO: loaded 3 dictionaries in 0.000s
2022-12-28 21:49:30,388 [Thread-11-machine] ERROR: discarding incomplete packet: b'0000'
2022-12-29 18:31:36,814 [Dummy-1] INFO: setting machine: Gemini PR
2022-12-29 18:31:36,815 [Dummy-1] INFO: loaded 3 dictionaries in 0.000s
2022-12-29 20:23:22,454 [Dummy-1] INFO: setting machine: Gemini PR
2022-12-29 20:23:22,457 [Dummy-1] INFO: loaded 3 dictionaries in 0.000s
2022-12-29 20:38:18,420 [Dummy-1] INFO: loading dictionary: /home/johannes/.local/share/plover/experiment.json
2022-12-29 20:38:18,420 [Dummy-1] INFO: loaded 4 dictionaries in 0.001s
2022-12-29 21:20:03,796 [Dummy-1] INFO: loaded 4 dictionaries in 0.000s
2022-12-29 21:20:03,885 [Dummy-1] INFO: loaded 4 dictionaries in 0.000s
2022-12-29 21:20:06,078 [Dummy-1] INFO: loaded 4 dictionaries in 0.000s
2022-12-29 21:20:06,204 [Dummy-1] INFO: loaded 4 dictionaries in 0.000s
2022-12-29 21:20:06,928 [Dummy-1] INFO: loaded 4 dictionaries in 0.000s
2022-12-29 21:20:07,653 [Dummy-1] INFO: loaded 4 dictionaries in 0.000s
2022-12-29 21:20:07,991 [Dummy-1] INFO: loaded 4 dictionaries in 0.000s
2022-12-29 21:20:08,380 [Dummy-1] INFO: loaded 4 dictionaries in 0.000s
2022-12-29 21:20:08,958 [Dummy-1] INFO: loaded 4 dictionaries in 0.000s
2022-12-29 21:20:09,089 [Dummy-1] INFO: loaded 4 dictionaries in 0.000s
2022-12-29 21:20:09,646 [Dummy-1] INFO: loaded 4 dictionaries in 0.000s
2022-12-29 21:20:10,201 [Dummy-1] INFO: loaded 4 dictionaries in 0.000s
2022-12-29 21:20:10,915 [Dummy-1] INFO: loaded 4 dictionaries in 0.000s
2022-12-29 21:20:11,043 [Dummy-1] INFO: loaded 4 dictionaries in 0.000s
2022-12-29 21:20:11,627 [Dummy-1] INFO: loaded 4 dictionaries in 0.000s
2022-12-29 21:20:14,849 [Dummy-1] INFO: loaded 4 dictionaries in 0.000s
2022-12-29 21:31:08,309 [MainThread] INFO: setting language to: en_US.UTF-8
2022-12-29 21:31:08,315 [MainThread] INFO: 38 custom mappings(s)
2022-12-29 21:31:08,382 [Dummy-1] INFO: set_stroke_filename(/home/johannes/.local/share/plover/strokes.log)
2022-12-29 21:31:08,382 [Dummy-1] INFO: loading system: English Stenotype
2022-12-29 21:31:08,490 [Dummy-1] INFO: setting machine: Gemini PR
2022-12-29 21:31:08,491 [Dummy-1] INFO: loading dictionary: /home/johannes/.local/share/plover/experiment.json
2022-12-29 21:31:08,492 [Dummy-1] INFO: loading dictionary: /home/johannes/.local/share/plover/user.json
2022-12-29 21:31:08,492 [Dummy-1] INFO: loading dictionary: /home/johannes/.local/share/plover/commands.json
2022-12-29 21:31:08,492 [Dummy-1] INFO: loading dictionary: /home/johannes/.local/share/plover/main.json
2022-12-29 21:31:08,817 [Dummy-1] INFO: loaded 4 dictionaries in 0.326s
2022-12-29 21:34:03,636 [MainThread] ERROR: Qt GUI error
Traceback (most recent call last):
  File "/home/runner/work/plover/plover/build/appimage/plover.AppDir/usr/lib/python3.9/site-packages/plover/gui_qt/dictionaries_widget.py", line 53, in _new_dictionary
  File "/home/runner/work/plover/plover/build/appimage/plover.AppDir/usr/lib/python3.9/site-packages/plover/dictionary/base.py", line 51, in create_dictionary
  File "/home/runner/work/plover/plover/build/appimage/plover.AppDir/usr/lib/python3.9/site-packages/plover/steno_dictionary.py", line 53, in create
ValueError: PythonDictionary does not support creation

The above exception was the direct cause of the following exception:

Traceback (most recent call last):
  File "/home/runner/work/plover/plover/build/appimage/plover.AppDir/usr/lib/python3.9/site-packages/plover/gui_qt/dictionaries_widget.py", line 649, in on_create_dictionary
  File "/home/runner/work/plover/plover/build/appimage/plover.AppDir/usr/lib/python3.9/contextlib.py", line 119, in __enter__
  File "/home/runner/work/plover/plover/build/appimage/plover.AppDir/usr/lib/python3.9/site-packages/plover/gui_qt/dictionaries_widget.py", line 57, in _new_dictionary
Exception: creating dictionary /home/johannes/.local/share/plover/experiment.py failed. PythonDictionary does not support creation
2022-12-29 21:35:15,995 [Dummy-1] INFO: loading dictionary: /home/johannes/.local/share/plover/experiment.py
2022-12-29 21:35:15,996 [Dummy-1] INFO: loaded 5 dictionaries in 0.001s
2022-12-29 21:36:09,586 [Dummy-1] INFO: loaded 5 dictionaries in 0.000s
2022-12-29 21:36:33,029 [MainThread] INFO: setting language to: en_US.UTF-8
2022-12-29 21:36:33,037 [MainThread] INFO: 38 custom mappings(s)
2022-12-29 21:36:33,177 [Dummy-1] INFO: set_stroke_filename(/home/johannes/.local/share/plover/strokes.log)
2022-12-29 21:36:33,177 [Dummy-1] INFO: loading system: English Stenotype
2022-12-29 21:36:33,315 [Dummy-1] INFO: setting machine: Gemini PR
2022-12-29 21:36:33,316 [Dummy-1] INFO: loading dictionary: /home/johannes/.local/share/plover/experiment.py
2022-12-29 21:36:33,316 [Dummy-1] INFO: loading dictionary: /home/johannes/.local/share/plover/experiment.json
2022-12-29 21:36:33,317 [Dummy-1] INFO: loading dictionary: /home/johannes/.local/share/plover/user.json
2022-12-29 21:36:33,317 [Dummy-1] INFO: loading dictionary: /home/johannes/.local/share/plover/commands.json
2022-12-29 21:36:33,317 [Dummy-1] INFO: loading dictionary: /home/johannes/.local/share/plover/main.json
2022-12-29 21:36:33,640 [Dummy-1] INFO: loaded 5 dictionaries in 0.324s
2022-12-29 21:37:00,496 [Dummy-1] INFO: loaded 5 dictionaries in 0.000s
2022-12-29 21:48:09,867 [Dummy-1] INFO: loaded 5 dictionaries in 0.000s
2022-12-29 22:05:50,397 [Dummy-1] INFO: loading dictionary: /home/johannes/.local/share/plover/experiment.py
2022-12-29 22:05:50,399 [Dummy-1] INFO: loaded 5 dictionaries in 0.001s
2022-12-29 22:05:50,399 [Dummy-1] ERROR: loading dictionary `experiment.py` failed: f-string expression part cannot include '#' (<string>, line 6)
2022-12-29 22:06:09,138 [Dummy-1] INFO: loaded 5 dictionaries in 0.000s
2022-12-29 22:06:10,060 [Dummy-1] INFO: loaded 5 dictionaries in 0.000s
2022-12-29 22:06:10,955 [Dummy-1] INFO: loaded 5 dictionaries in 0.000s
2022-12-29 22:06:17,334 [Dummy-1] INFO: loaded 5 dictionaries in 0.000s
2022-12-29 22:06:18,194 [Dummy-1] INFO: loaded 5 dictionaries in 0.000s
2022-12-29 22:06:19,091 [Dummy-1] INFO: loaded 5 dictionaries in 0.000s
2022-12-29 22:06:19,863 [Dummy-1] INFO: loaded 5 dictionaries in 0.000s
2022-12-29 22:12:36,417 [Dummy-1] INFO: loading dictionary: /home/johannes/.local/share/plover/experiment.py
2022-12-29 22:12:36,418 [Dummy-1] INFO: loaded 5 dictionaries in 0.001s
2022-12-29 22:12:36,937 [Dummy-1] INFO: loaded 5 dictionaries in 0.000s
2022-12-29 22:12:38,964 [Dummy-1] INFO: loaded 5 dictionaries in 0.000s
2022-12-29 22:12:39,543 [Dummy-1] INFO: loaded 5 dictionaries in 0.000s
2022-12-29 22:13:52,764 [Dummy-1] INFO: loading dictionary: /home/johannes/.local/share/plover/experiment.py
2022-12-29 22:13:52,765 [Dummy-1] INFO: loaded 5 dictionaries in 0.001s
2022-12-29 22:13:53,570 [Dummy-1] INFO: loaded 5 dictionaries in 0.000s
2022-12-29 22:13:54,727 [Dummy-1] INFO: loaded 5 dictionaries in 0.000s
2022-12-29 22:13:55,272 [Dummy-1] INFO: loaded 5 dictionaries in 0.000s
2022-12-29 22:13:56,791 [Dummy-1] INFO: loaded 5 dictionaries in 0.000s
2022-12-29 22:15:05,115 [Dummy-1] INFO: loading dictionary: /home/johannes/.local/share/plover/experiment.py
2022-12-29 22:15:05,116 [Dummy-1] INFO: loaded 5 dictionaries in 0.001s
2022-12-29 22:15:11,547 [Dummy-1] INFO: loading dictionary: /home/johannes/.local/share/plover/experiment.py
2022-12-29 22:15:11,549 [Dummy-1] INFO: loaded 5 dictionaries in 0.002s
2022-12-29 22:15:12,012 [Dummy-1] INFO: loaded 5 dictionaries in 0.000s
2022-12-29 22:16:10,520 [Dummy-1] INFO: loading dictionary: /home/johannes/.local/share/plover/experiment.py
2022-12-29 22:16:10,521 [Dummy-1] INFO: loaded 5 dictionaries in 0.001s
2022-12-29 22:16:10,979 [Dummy-1] INFO: loaded 5 dictionaries in 0.000s
2022-12-29 22:16:12,598 [Dummy-1] INFO: loaded 5 dictionaries in 0.000s
2022-12-29 22:16:13,046 [Dummy-1] INFO: loaded 5 dictionaries in 0.000s
2022-12-29 22:16:16,858 [Dummy-1] ERROR: engine on_stroked failed
Traceback (most recent call last):
  File "/home/runner/work/plover/plover/build/appimage/plover.AppDir/usr/lib/python3.9/site-packages/plover/engine.py", line 147, in run
  File "/home/runner/work/plover/plover/build/appimage/plover.AppDir/usr/lib/python3.9/site-packages/plover/engine.py", line 382, in _on_stroked
  File "/home/runner/work/plover/plover/build/appimage/plover.AppDir/usr/lib/python3.9/site-packages/plover/translation.py", line 204, in translate
  File "/home/runner/work/plover/plover/build/appimage/plover.AppDir/usr/lib/python3.9/site-packages/plover/translation.py", line 296, in translate_stroke
  File "/home/runner/work/plover/plover/build/appimage/plover.AppDir/usr/lib/python3.9/site-packages/plover/translation.py", line 455, in _lookup_with_prefix
  File "/home/runner/work/plover/plover/build/appimage/plover.AppDir/usr/lib/python3.9/site-packages/plover/translation.py", line 405, in _lookup_with_suffix
  File "/home/runner/work/plover/plover/build/appimage/plover.AppDir/usr/lib/python3.9/site-packages/plover/translation.py", line 391, in _lookup_strokes
  File "/home/runner/work/plover/plover/build/appimage/plover.AppDir/usr/lib/python3.9/site-packages/plover/steno_dictionary.py", line 226, in lookup
  File "/home/runner/work/plover/plover/build/appimage/plover.AppDir/usr/lib/python3.9/site-packages/plover/steno_dictionary.py", line 192, in _lookup
  File "/home/johannes/.local/share/plover/plugins/linux/lib/python3.9/site-packages/plover_python_dictionary.py", line 56, in get
    return self._lookup(key)
  File "<string>", line 5, in lookup
IndexError: tuple index out of range
2022-12-29 22:16:46,242 [Dummy-1] INFO: loading dictionary: /home/johannes/.local/share/plover/experiment.py
2022-12-29 22:16:46,243 [Dummy-1] INFO: loaded 5 dictionaries in 0.000s
2022-12-29 22:16:47,583 [Dummy-1] INFO: loaded 5 dictionaries in 0.000s
2022-12-29 22:16:50,410 [Dummy-1] ERROR: engine on_stroked failed
Traceback (most recent call last):
  File "/home/runner/work/plover/plover/build/appimage/plover.AppDir/usr/lib/python3.9/site-packages/plover/engine.py", line 147, in run
  File "/home/runner/work/plover/plover/build/appimage/plover.AppDir/usr/lib/python3.9/site-packages/plover/engine.py", line 382, in _on_stroked
  File "/home/runner/work/plover/plover/build/appimage/plover.AppDir/usr/lib/python3.9/site-packages/plover/translation.py", line 204, in translate
  File "/home/runner/work/plover/plover/build/appimage/plover.AppDir/usr/lib/python3.9/site-packages/plover/translation.py", line 296, in translate_stroke
  File "/home/runner/work/plover/plover/build/appimage/plover.AppDir/usr/lib/python3.9/site-packages/plover/translation.py", line 455, in _lookup_with_prefix
  File "/home/runner/work/plover/plover/build/appimage/plover.AppDir/usr/lib/python3.9/site-packages/plover/translation.py", line 405, in _lookup_with_suffix
  File "/home/runner/work/plover/plover/build/appimage/plover.AppDir/usr/lib/python3.9/site-packages/plover/translation.py", line 391, in _lookup_strokes
  File "/home/runner/work/plover/plover/build/appimage/plover.AppDir/usr/lib/python3.9/site-packages/plover/steno_dictionary.py", line 226, in lookup
  File "/home/runner/work/plover/plover/build/appimage/plover.AppDir/usr/lib/python3.9/site-packages/plover/steno_dictionary.py", line 192, in _lookup
  File "/home/johannes/.local/share/plover/plugins/linux/lib/python3.9/site-packages/plover_python_dictionary.py", line 56, in get
    return self._lookup(key)
  File "<string>", line 5, in lookup
AssertionError
2022-12-29 22:17:12,913 [Dummy-1] INFO: loading dictionary: /home/johannes/.local/share/plover/experiment.py
2022-12-29 22:17:12,914 [Dummy-1] INFO: loaded 5 dictionaries in 0.001s
2022-12-29 22:17:14,489 [Dummy-1] INFO: loaded 5 dictionaries in 0.000s
2022-12-29 22:17:18,269 [Dummy-1] INFO: loaded 5 dictionaries in 0.000s
2022-12-29 22:17:21,288 [Dummy-1] INFO: loaded 5 dictionaries in 0.000s
2022-12-29 22:17:26,698 [Dummy-1] INFO: loaded 5 dictionaries in 0.000s
2022-12-29 22:17:27,778 [Dummy-1] INFO: loaded 5 dictionaries in 0.000s
2022-12-29 22:18:33,111 [Dummy-1] INFO: loading dictionary: /home/johannes/.local/share/plover/experiment.py
2022-12-29 22:18:33,130 [Dummy-1] INFO: loaded 5 dictionaries in 0.018s
2022-12-29 22:18:34,663 [Dummy-1] INFO: loaded 5 dictionaries in 0.000s
2022-12-29 22:19:06,991 [Dummy-1] INFO: loading dictionary: /home/johannes/.local/share/plover/experiment.py
2022-12-29 22:19:06,992 [Dummy-1] INFO: loaded 5 dictionaries in 0.002s
2022-12-29 22:19:07,395 [Dummy-1] INFO: loaded 5 dictionaries in 0.000s
2022-12-29 22:19:48,619 [Dummy-1] INFO: loading dictionary: /home/johannes/.local/share/plover/experiment.py
2022-12-29 22:19:48,620 [Dummy-1] INFO: loaded 5 dictionaries in 0.001s
2022-12-29 22:19:49,594 [Dummy-1] INFO: loaded 5 dictionaries in 0.000s
2022-12-29 22:20:08,272 [Dummy-1] INFO: loaded 5 dictionaries in 0.000s
2022-12-29 22:20:08,812 [Dummy-1] INFO: loaded 5 dictionaries in 0.000s
2022-12-29 22:20:10,260 [Dummy-1] INFO: loaded 5 dictionaries in 0.000s
2022-12-29 22:20:10,929 [Dummy-1] INFO: loaded 5 dictionaries in 0.000s
2022-12-29 22:21:04,287 [Dummy-1] INFO: loading dictionary: /home/johannes/.local/share/plover/experiment.py
2022-12-29 22:21:04,289 [Dummy-1] INFO: loaded 5 dictionaries in 0.002s
2022-12-29 22:21:04,691 [Dummy-1] INFO: loaded 5 dictionaries in 0.000s
2022-12-29 22:21:06,232 [Dummy-1] INFO: loaded 5 dictionaries in 0.000s
2022-12-29 22:21:07,377 [Dummy-1] INFO: loaded 5 dictionaries in 0.000s
2022-12-29 22:22:30,058 [Dummy-1] INFO: loading dictionary: /home/johannes/.local/share/plover/experiment.py
2022-12-29 22:22:30,060 [Dummy-1] INFO: loaded 5 dictionaries in 0.002s
2022-12-29 22:22:30,486 [Dummy-1] INFO: loaded 5 dictionaries in 0.000s
2022-12-29 22:22:32,001 [Dummy-1] INFO: loaded 5 dictionaries in 0.000s
2022-12-29 22:22:33,459 [Dummy-1] INFO: loaded 5 dictionaries in 0.000s
2022-12-29 22:23:10,260 [Dummy-1] INFO: loading dictionary: /home/johannes/.local/share/plover/experiment.py
2022-12-29 22:23:10,261 [Dummy-1] INFO: loaded 5 dictionaries in 0.001s
2022-12-29 22:23:10,695 [Dummy-1] INFO: loaded 5 dictionaries in 0.000s
2022-12-29 22:23:11,991 [Dummy-1] INFO: loaded 5 dictionaries in 0.000s
2022-12-29 22:23:14,433 [Dummy-1] INFO: loaded 5 dictionaries in 0.000s
2022-12-29 22:23:53,831 [Dummy-1] INFO: loading dictionary: /home/johannes/.local/share/plover/experiment.py
2022-12-29 22:23:53,832 [Dummy-1] INFO: loaded 5 dictionaries in 0.001s
2022-12-29 22:23:54,240 [Dummy-1] INFO: loaded 5 dictionaries in 0.000s
2022-12-29 22:24:10,266 [Dummy-1] INFO: loading dictionary: /home/johannes/.local/share/plover/experiment.py
2022-12-29 22:24:10,268 [Dummy-1] INFO: loaded 5 dictionaries in 0.002s
2022-12-29 22:24:10,949 [Dummy-1] INFO: loaded 5 dictionaries in 0.000s
2022-12-29 22:24:27,543 [Dummy-1] INFO: loading dictionary: /home/johannes/.local/share/plover/experiment.py
2022-12-29 22:24:27,544 [Dummy-1] INFO: loaded 5 dictionaries in 0.002s
2022-12-29 22:24:27,806 [Dummy-1] INFO: loaded 5 dictionaries in 0.000s
2022-12-29 22:24:51,640 [Dummy-1] INFO: loaded 5 dictionaries in 0.000s
2022-12-29 22:24:52,244 [Dummy-1] INFO: loaded 5 dictionaries in 0.000s
2022-12-29 22:25:08,898 [Dummy-1] INFO: loading dictionary: /home/johannes/.local/share/plover/experiment.py
2022-12-29 22:25:08,899 [Dummy-1] INFO: loaded 5 dictionaries in 0.000s
2022-12-29 22:25:09,198 [Dummy-1] INFO: loaded 5 dictionaries in 0.000s
2022-12-29 22:28:41,207 [Dummy-1] INFO: loading dictionary: /home/johannes/.local/share/plover/experiment.py
2022-12-29 22:28:41,207 [Dummy-1] INFO: loaded 5 dictionaries in 0.001s
2022-12-29 22:28:41,392 [Dummy-1] INFO: loaded 5 dictionaries in 0.000s
2022-12-29 22:28:47,099 [Dummy-1] ERROR: engine on_stroked failed
Traceback (most recent call last):
  File "/home/runner/work/plover/plover/build/appimage/plover.AppDir/usr/lib/python3.9/site-packages/plover/engine.py", line 147, in run
  File "/home/runner/work/plover/plover/build/appimage/plover.AppDir/usr/lib/python3.9/site-packages/plover/engine.py", line 382, in _on_stroked
  File "/home/runner/work/plover/plover/build/appimage/plover.AppDir/usr/lib/python3.9/site-packages/plover/translation.py", line 205, in translate
  File "/home/runner/work/plover/plover/build/appimage/plover.AppDir/usr/lib/python3.9/site-packages/plover/translation.py", line 261, in flush
  File "/home/runner/work/plover/plover/build/appimage/plover.AppDir/usr/lib/python3.9/site-packages/plover/translation.py", line 266, in _output
  File "/home/runner/work/plover/plover/build/appimage/plover.AppDir/usr/lib/python3.9/site-packages/plover/formatting.py", line 449, in format
  File "/home/runner/work/plover/plover/build/appimage/plover.AppDir/usr/lib/python3.9/site-packages/plover/formatting.py", line 565, in render
  File "/home/runner/work/plover/plover/build/appimage/plover.AppDir/usr/lib/python3.9/site-packages/plover/engine.py", line 405, in _send_key_combination
  File "/home/runner/work/plover/plover/build/appimage/plover.AppDir/usr/lib/python3.9/site-packages/plover/oslayer/linux/keyboardcontrol_x11.py", line 1239, in send_key_combination
  File "/home/runner/work/plover/plover/build/appimage/plover.AppDir/usr/lib/python3.9/site-packages/plover/key_combo.py", line 200, in parse_key_combo
  File "/home/runner/work/plover/plover/build/appimage/plover.AppDir/usr/lib/python3.9/site-packages/plover/key_combo.py", line 157, in _raise_error
SyntaxError: unbalanced "(" in "Control_L(1[]"
2022-12-29 22:29:31,004 [Dummy-1] INFO: loading dictionary: /home/johannes/.local/share/plover/experiment.py
2022-12-29 22:29:31,004 [Dummy-1] INFO: loaded 5 dictionaries in 0.001s
2022-12-29 22:29:31,170 [Dummy-1] INFO: loaded 5 dictionaries in 0.000s
2022-12-29 22:29:35,940 [Dummy-1] ERROR: engine on_stroked failed
Traceback (most recent call last):
  File "/home/runner/work/plover/plover/build/appimage/plover.AppDir/usr/lib/python3.9/site-packages/plover/engine.py", line 147, in run
  File "/home/runner/work/plover/plover/build/appimage/plover.AppDir/usr/lib/python3.9/site-packages/plover/engine.py", line 382, in _on_stroked
  File "/home/runner/work/plover/plover/build/appimage/plover.AppDir/usr/lib/python3.9/site-packages/plover/translation.py", line 205, in translate
  File "/home/runner/work/plover/plover/build/appimage/plover.AppDir/usr/lib/python3.9/site-packages/plover/translation.py", line 261, in flush
  File "/home/runner/work/plover/plover/build/appimage/plover.AppDir/usr/lib/python3.9/site-packages/plover/translation.py", line 266, in _output
  File "/home/runner/work/plover/plover/build/appimage/plover.AppDir/usr/lib/python3.9/site-packages/plover/formatting.py", line 449, in format
  File "/home/runner/work/plover/plover/build/appimage/plover.AppDir/usr/lib/python3.9/site-packages/plover/formatting.py", line 565, in render
  File "/home/runner/work/plover/plover/build/appimage/plover.AppDir/usr/lib/python3.9/site-packages/plover/engine.py", line 405, in _send_key_combination
  File "/home/runner/work/plover/plover/build/appimage/plover.AppDir/usr/lib/python3.9/site-packages/plover/oslayer/linux/keyboardcontrol_x11.py", line 1239, in send_key_combination
  File "/home/runner/work/plover/plover/build/appimage/plover.AppDir/usr/lib/python3.9/site-packages/plover/key_combo.py", line 200, in parse_key_combo
  File "/home/runner/work/plover/plover/build/appimage/plover.AppDir/usr/lib/python3.9/site-packages/plover/key_combo.py", line 157, in _raise_error
SyntaxError: unbalanced "(" in "Control_L(1[]"
2022-12-29 22:30:15,088 [Dummy-1] ERROR: engine on_stroked failed
Traceback (most recent call last):
  File "/home/runner/work/plover/plover/build/appimage/plover.AppDir/usr/lib/python3.9/site-packages/plover/engine.py", line 147, in run
  File "/home/runner/work/plover/plover/build/appimage/plover.AppDir/usr/lib/python3.9/site-packages/plover/engine.py", line 382, in _on_stroked
  File "/home/runner/work/plover/plover/build/appimage/plover.AppDir/usr/lib/python3.9/site-packages/plover/translation.py", line 205, in translate
  File "/home/runner/work/plover/plover/build/appimage/plover.AppDir/usr/lib/python3.9/site-packages/plover/translation.py", line 261, in flush
  File "/home/runner/work/plover/plover/build/appimage/plover.AppDir/usr/lib/python3.9/site-packages/plover/translation.py", line 266, in _output
  File "/home/runner/work/plover/plover/build/appimage/plover.AppDir/usr/lib/python3.9/site-packages/plover/formatting.py", line 449, in format
  File "/home/runner/work/plover/plover/build/appimage/plover.AppDir/usr/lib/python3.9/site-packages/plover/formatting.py", line 565, in render
  File "/home/runner/work/plover/plover/build/appimage/plover.AppDir/usr/lib/python3.9/site-packages/plover/engine.py", line 405, in _send_key_combination
  File "/home/runner/work/plover/plover/build/appimage/plover.AppDir/usr/lib/python3.9/site-packages/plover/oslayer/linux/keyboardcontrol_x11.py", line 1239, in send_key_combination
  File "/home/runner/work/plover/plover/build/appimage/plover.AppDir/usr/lib/python3.9/site-packages/plover/key_combo.py", line 200, in parse_key_combo
  File "/home/runner/work/plover/plover/build/appimage/plover.AppDir/usr/lib/python3.9/site-packages/plover/key_combo.py", line 157, in _raise_error
SyntaxError: unbalanced "(" in "Control_L(1[]"
2022-12-29 22:30:34,566 [Dummy-1] ERROR: engine on_stroked failed
Traceback (most recent call last):
  File "/home/runner/work/plover/plover/build/appimage/plover.AppDir/usr/lib/python3.9/site-packages/plover/engine.py", line 147, in run
  File "/home/runner/work/plover/plover/build/appimage/plover.AppDir/usr/lib/python3.9/site-packages/plover/engine.py", line 382, in _on_stroked
  File "/home/runner/work/plover/plover/build/appimage/plover.AppDir/usr/lib/python3.9/site-packages/plover/translation.py", line 205, in translate
  File "/home/runner/work/plover/plover/build/appimage/plover.AppDir/usr/lib/python3.9/site-packages/plover/translation.py", line 261, in flush
  File "/home/runner/work/plover/plover/build/appimage/plover.AppDir/usr/lib/python3.9/site-packages/plover/translation.py", line 266, in _output
  File "/home/runner/work/plover/plover/build/appimage/plover.AppDir/usr/lib/python3.9/site-packages/plover/formatting.py", line 449, in format
  File "/home/runner/work/plover/plover/build/appimage/plover.AppDir/usr/lib/python3.9/site-packages/plover/formatting.py", line 565, in render
  File "/home/runner/work/plover/plover/build/appimage/plover.AppDir/usr/lib/python3.9/site-packages/plover/engine.py", line 405, in _send_key_combination
  File "/home/runner/work/plover/plover/build/appimage/plover.AppDir/usr/lib/python3.9/site-packages/plover/oslayer/linux/keyboardcontrol_x11.py", line 1239, in send_key_combination
  File "/home/runner/work/plover/plover/build/appimage/plover.AppDir/usr/lib/python3.9/site-packages/plover/key_combo.py", line 200, in parse_key_combo
  File "/home/runner/work/plover/plover/build/appimage/plover.AppDir/usr/lib/python3.9/site-packages/plover/key_combo.py", line 157, in _raise_error
SyntaxError: unbalanced "(" in "Control_L(1[]"
2022-12-29 22:30:36,300 [Dummy-1] ERROR: engine on_stroked failed
Traceback (most recent call last):
  File "/home/runner/work/plover/plover/build/appimage/plover.AppDir/usr/lib/python3.9/site-packages/plover/engine.py", line 147, in run
  File "/home/runner/work/plover/plover/build/appimage/plover.AppDir/usr/lib/python3.9/site-packages/plover/engine.py", line 382, in _on_stroked
  File "/home/runner/work/plover/plover/build/appimage/plover.AppDir/usr/lib/python3.9/site-packages/plover/translation.py", line 205, in translate
  File "/home/runner/work/plover/plover/build/appimage/plover.AppDir/usr/lib/python3.9/site-packages/plover/translation.py", line 261, in flush
  File "/home/runner/work/plover/plover/build/appimage/plover.AppDir/usr/lib/python3.9/site-packages/plover/translation.py", line 266, in _output
  File "/home/runner/work/plover/plover/build/appimage/plover.AppDir/usr/lib/python3.9/site-packages/plover/formatting.py", line 449, in format
  File "/home/runner/work/plover/plover/build/appimage/plover.AppDir/usr/lib/python3.9/site-packages/plover/formatting.py", line 565, in render
  File "/home/runner/work/plover/plover/build/appimage/plover.AppDir/usr/lib/python3.9/site-packages/plover/engine.py", line 405, in _send_key_combination
  File "/home/runner/work/plover/plover/build/appimage/plover.AppDir/usr/lib/python3.9/site-packages/plover/oslayer/linux/keyboardcontrol_x11.py", line 1239, in send_key_combination
  File "/home/runner/work/plover/plover/build/appimage/plover.AppDir/usr/lib/python3.9/site-packages/plover/key_combo.py", line 200, in parse_key_combo
  File "/home/runner/work/plover/plover/build/appimage/plover.AppDir/usr/lib/python3.9/site-packages/plover/key_combo.py", line 157, in _raise_error
SyntaxError: unbalanced "(" in "Control_L(1[]"
2022-12-29 22:30:39,551 [Dummy-1] ERROR: engine on_stroked failed
Traceback (most recent call last):
  File "/home/runner/work/plover/plover/build/appimage/plover.AppDir/usr/lib/python3.9/site-packages/plover/engine.py", line 147, in run
  File "/home/runner/work/plover/plover/build/appimage/plover.AppDir/usr/lib/python3.9/site-packages/plover/engine.py", line 382, in _on_stroked
  File "/home/runner/work/plover/plover/build/appimage/plover.AppDir/usr/lib/python3.9/site-packages/plover/translation.py", line 205, in translate
  File "/home/runner/work/plover/plover/build/appimage/plover.AppDir/usr/lib/python3.9/site-packages/plover/translation.py", line 261, in flush
  File "/home/runner/work/plover/plover/build/appimage/plover.AppDir/usr/lib/python3.9/site-packages/plover/translation.py", line 266, in _output
  File "/home/runner/work/plover/plover/build/appimage/plover.AppDir/usr/lib/python3.9/site-packages/plover/formatting.py", line 449, in format
  File "/home/runner/work/plover/plover/build/appimage/plover.AppDir/usr/lib/python3.9/site-packages/plover/formatting.py", line 565, in render
  File "/home/runner/work/plover/plover/build/appimage/plover.AppDir/usr/lib/python3.9/site-packages/plover/engine.py", line 405, in _send_key_combination
  File "/home/runner/work/plover/plover/build/appimage/plover.AppDir/usr/lib/python3.9/site-packages/plover/oslayer/linux/keyboardcontrol_x11.py", line 1239, in send_key_combination
  File "/home/runner/work/plover/plover/build/appimage/plover.AppDir/usr/lib/python3.9/site-packages/plover/key_combo.py", line 200, in parse_key_combo
  File "/home/runner/work/plover/plover/build/appimage/plover.AppDir/usr/lib/python3.9/site-packages/plover/key_combo.py", line 157, in _raise_error
SyntaxError: unbalanced "(" in "Control_L(1[]"
2022-12-29 22:37:29,216 [Dummy-1] INFO: loading dictionary: /home/johannes/.local/share/plover/experiment.py
2022-12-29 22:37:29,218 [Dummy-1] INFO: loaded 5 dictionaries in 0.002s
2022-12-29 22:37:29,548 [Dummy-1] INFO: loaded 5 dictionaries in 0.000s
2022-12-29 22:37:36,307 [Dummy-1] ERROR: engine on_stroked failed
Traceback (most recent call last):
  File "/home/runner/work/plover/plover/build/appimage/plover.AppDir/usr/lib/python3.9/site-packages/plover/engine.py", line 147, in run
  File "/home/runner/work/plover/plover/build/appimage/plover.AppDir/usr/lib/python3.9/site-packages/plover/engine.py", line 382, in _on_stroked
  File "/home/runner/work/plover/plover/build/appimage/plover.AppDir/usr/lib/python3.9/site-packages/plover/translation.py", line 204, in translate
  File "/home/runner/work/plover/plover/build/appimage/plover.AppDir/usr/lib/python3.9/site-packages/plover/translation.py", line 296, in translate_stroke
  File "/home/runner/work/plover/plover/build/appimage/plover.AppDir/usr/lib/python3.9/site-packages/plover/translation.py", line 451, in _lookup_with_prefix
  File "/home/runner/work/plover/plover/build/appimage/plover.AppDir/usr/lib/python3.9/site-packages/plover/translation.py", line 405, in _lookup_with_suffix
  File "/home/runner/work/plover/plover/build/appimage/plover.AppDir/usr/lib/python3.9/site-packages/plover/translation.py", line 391, in _lookup_strokes
  File "/home/runner/work/plover/plover/build/appimage/plover.AppDir/usr/lib/python3.9/site-packages/plover/steno_dictionary.py", line 226, in lookup
  File "/home/runner/work/plover/plover/build/appimage/plover.AppDir/usr/lib/python3.9/site-packages/plover/steno_dictionary.py", line 192, in _lookup
  File "/home/johannes/.local/share/plover/plugins/linux/lib/python3.9/site-packages/plover_python_dictionary.py", line 56, in get
    return self._lookup(key)
  File "<string>", line 12, in lookup
TypeError: map() must have at least two arguments.
2022-12-29 22:37:46,667 [Dummy-1] INFO: loading dictionary: /home/johannes/.local/share/plover/experiment.py
2022-12-29 22:37:46,669 [Dummy-1] INFO: loaded 5 dictionaries in 0.002s
2022-12-29 22:37:46,872 [Dummy-1] INFO: loaded 5 dictionaries in 0.000s
2022-12-29 22:40:35,643 [Dummy-1] INFO: loading dictionary: /home/johannes/.local/share/plover/experiment.py
2022-12-29 22:40:35,645 [Dummy-1] INFO: loaded 5 dictionaries in 0.002s
2022-12-29 22:40:35,790 [Dummy-1] INFO: loaded 5 dictionaries in 0.000s
2022-12-29 22:41:02,442 [Dummy-1] INFO: loading dictionary: /home/johannes/.local/share/plover/experiment.py
2022-12-29 22:41:02,443 [Dummy-1] INFO: loaded 5 dictionaries in 0.001s
2022-12-29 22:41:02,562 [Dummy-1] INFO: loaded 5 dictionaries in 0.000s
2022-12-29 22:45:17,833 [Dummy-1] INFO: loading dictionary: /home/johannes/.local/share/plover/experiment.py
2022-12-29 22:45:17,834 [Dummy-1] INFO: loaded 5 dictionaries in 0.001s
2022-12-29 22:45:18,128 [Dummy-1] INFO: loaded 5 dictionaries in 0.000s
2022-12-29 23:55:37,493 [Dummy-1] INFO: loading dictionary: /home/johannes/.local/share/plover/experiment.py
2022-12-29 23:55:37,691 [Dummy-1] INFO: loaded 5 dictionaries in 0.199s
2022-12-29 23:55:37,915 [Dummy-1] INFO: loaded 5 dictionaries in 0.000s
2022-12-29 23:57:48,603 [Dummy-1] INFO: loading dictionary: /home/johannes/.local/share/plover/experiment.py
2022-12-29 23:57:48,741 [Dummy-1] INFO: loaded 5 dictionaries in 0.138s
2022-12-29 23:57:49,035 [Dummy-1] INFO: loaded 5 dictionaries in 0.000s
2022-12-30 00:06:19,169 [Dummy-1] INFO: loading dictionary: /home/johannes/.local/share/plover/experiment.py
2022-12-30 00:06:19,296 [Dummy-1] INFO: loaded 5 dictionaries in 0.127s
2022-12-30 00:06:19,598 [Dummy-1] INFO: loaded 5 dictionaries in 0.000s
2022-12-30 00:06:26,953 [Dummy-1] ERROR: engine on_stroked failed
Traceback (most recent call last):
  File "/home/runner/work/plover/plover/build/appimage/plover.AppDir/usr/lib/python3.9/site-packages/plover/engine.py", line 147, in run
  File "/home/runner/work/plover/plover/build/appimage/plover.AppDir/usr/lib/python3.9/site-packages/plover/engine.py", line 382, in _on_stroked
  File "/home/runner/work/plover/plover/build/appimage/plover.AppDir/usr/lib/python3.9/site-packages/plover/translation.py", line 204, in translate
  File "/home/runner/work/plover/plover/build/appimage/plover.AppDir/usr/lib/python3.9/site-packages/plover/translation.py", line 296, in translate_stroke
  File "/home/runner/work/plover/plover/build/appimage/plover.AppDir/usr/lib/python3.9/site-packages/plover/translation.py", line 451, in _lookup_with_prefix
  File "/home/runner/work/plover/plover/build/appimage/plover.AppDir/usr/lib/python3.9/site-packages/plover/translation.py", line 405, in _lookup_with_suffix
  File "/home/runner/work/plover/plover/build/appimage/plover.AppDir/usr/lib/python3.9/site-packages/plover/translation.py", line 391, in _lookup_strokes
  File "/home/runner/work/plover/plover/build/appimage/plover.AppDir/usr/lib/python3.9/site-packages/plover/steno_dictionary.py", line 226, in lookup
  File "/home/runner/work/plover/plover/build/appimage/plover.AppDir/usr/lib/python3.9/site-packages/plover/steno_dictionary.py", line 192, in _lookup
  File "/home/johannes/.local/share/plover/plugins/linux/lib/python3.9/site-packages/plover_python_dictionary.py", line 56, in get
    return self._lookup(key)
  File "<string>", line 22, in lookup
TypeError: 'type' object is not iterable
2022-12-30 00:06:53,838 [Dummy-1] INFO: loading dictionary: /home/johannes/.local/share/plover/experiment.py
2022-12-30 00:06:53,968 [Dummy-1] INFO: loaded 5 dictionaries in 0.130s
2022-12-30 00:06:54,260 [Dummy-1] INFO: loaded 5 dictionaries in 0.000s
2022-12-30 00:19:53,760 [Dummy-1] INFO: loading dictionary: /home/johannes/.local/share/plover/experiment.py
2022-12-30 00:19:53,943 [Dummy-1] INFO: loaded 5 dictionaries in 0.183s
2022-12-30 00:19:54,199 [Dummy-1] INFO: loaded 5 dictionaries in 0.000s
2022-12-30 00:19:59,058 [Dummy-1] ERROR: engine on_stroked failed
Traceback (most recent call last):
  File "/home/runner/work/plover/plover/build/appimage/plover.AppDir/usr/lib/python3.9/site-packages/plover/engine.py", line 147, in run
  File "/home/runner/work/plover/plover/build/appimage/plover.AppDir/usr/lib/python3.9/site-packages/plover/engine.py", line 382, in _on_stroked
  File "/home/runner/work/plover/plover/build/appimage/plover.AppDir/usr/lib/python3.9/site-packages/plover/translation.py", line 204, in translate
  File "/home/runner/work/plover/plover/build/appimage/plover.AppDir/usr/lib/python3.9/site-packages/plover/translation.py", line 296, in translate_stroke
  File "/home/runner/work/plover/plover/build/appimage/plover.AppDir/usr/lib/python3.9/site-packages/plover/translation.py", line 455, in _lookup_with_prefix
  File "/home/runner/work/plover/plover/build/appimage/plover.AppDir/usr/lib/python3.9/site-packages/plover/translation.py", line 405, in _lookup_with_suffix
  File "/home/runner/work/plover/plover/build/appimage/plover.AppDir/usr/lib/python3.9/site-packages/plover/translation.py", line 391, in _lookup_strokes
  File "/home/runner/work/plover/plover/build/appimage/plover.AppDir/usr/lib/python3.9/site-packages/plover/steno_dictionary.py", line 226, in lookup
  File "/home/runner/work/plover/plover/build/appimage/plover.AppDir/usr/lib/python3.9/site-packages/plover/steno_dictionary.py", line 192, in _lookup
  File "/home/johannes/.local/share/plover/plugins/linux/lib/python3.9/site-packages/plover_python_dictionary.py", line 56, in get
    return self._lookup(key)
  File "<string>", line 24, in lookup
IndexError: tuple index out of range
2022-12-30 00:21:00,710 [Dummy-1] INFO: loading dictionary: /home/johannes/.local/share/plover/experiment.py
2022-12-30 00:21:00,886 [Dummy-1] INFO: loaded 5 dictionaries in 0.176s
2022-12-30 00:21:02,483 [Dummy-1] INFO: loaded 5 dictionaries in 0.000s
2022-12-30 00:25:35,092 [Dummy-1] INFO: loading dictionary: /home/johannes/.local/share/plover/experiment.py
2022-12-30 00:25:35,215 [Dummy-1] INFO: loaded 5 dictionaries in 0.123s
2022-12-30 00:25:36,982 [Dummy-1] INFO: loaded 5 dictionaries in 0.000s
2022-12-30 00:31:52,872 [Dummy-1] INFO: loading dictionary: /home/johannes/.local/share/plover/experiment.py
2022-12-30 00:31:52,962 [Dummy-1] INFO: loaded 5 dictionaries in 0.090s
2022-12-30 00:31:53,363 [Dummy-1] INFO: loaded 5 dictionaries in 0.000s
